2022-05-30 05:37:45,915 - INFO -Bot: Анонимный Чат Телеграм | Telegram XChat [@AnonimXChat_robot]
2022-05-30 05:37:46,300 - WARNING -Updates were skipped successfully.
2022-05-30 05:37:46,301 - INFO -Start polling.
2022-05-30 05:38:18,425 - WARNING -'NoneType' object is not subscriptable
2022-05-30 05:38:18,727 - ERROR -Task exception was never retrieved
future: <Task finished name='Task-16' coro=<Dispatcher._process_polling_updates() done, defined at /home/wish/Projects/AnonimXChat/AnonChatTg/venv/lib/python3.10/site-packages/aiogram/dispatcher/dispatcher.py:407> exception=ChatNotFound('Chat not found')>
Traceback (most recent call last):
  File "/home/wish/Projects/AnonimXChat/AnonChatTg/main.py", line 194, in chating
    await bot.send_message(db.select_connect_with(message.from_user.id)[0],user_data['msg'])
TypeError: 'NoneType' object is not subscriptable

During handling of the above exception, another exception occurred:

Traceback (most recent call last):
  File "/home/wish/Projects/AnonimXChat/AnonChatTg/venv/lib/python3.10/site-packages/aiogram/dispatcher/dispatcher.py", line 415, in _process_polling_updates
    for responses in itertools.chain.from_iterable(await self.process_updates(updates, fast)):
  File "/home/wish/Projects/AnonimXChat/AnonChatTg/venv/lib/python3.10/site-packages/aiogram/dispatcher/dispatcher.py", line 235, in process_updates
    return await asyncio.gather(*tasks)
  File "/home/wish/Projects/AnonimXChat/AnonChatTg/venv/lib/python3.10/site-packages/aiogram/dispatcher/handler.py", line 116, in notify
    response = await handler_obj.handler(*args, **partial_data)
  File "/home/wish/Projects/AnonimXChat/AnonChatTg/venv/lib/python3.10/site-packages/aiogram/dispatcher/dispatcher.py", line 256, in process_update
    return await self.message_handlers.notify(update.message)
  File "/home/wish/Projects/AnonimXChat/AnonChatTg/venv/lib/python3.10/site-packages/aiogram/dispatcher/handler.py", line 116, in notify
    response = await handler_obj.handler(*args, **partial_data)
  File "/home/wish/Projects/AnonimXChat/AnonChatTg/main.py", line 208, in chating
    await send_to_channel_log_exception(message,e)
  File "/home/wish/Projects/AnonimXChat/AnonChatTg/main.py", line 242, in send_to_channel_log_exception
    await bot.send_message(-111111111,f'Ошибка\n\n{except_name}')
  File "/home/wish/Projects/AnonimXChat/AnonChatTg/venv/lib/python3.10/site-packages/aiogram/bot/bot.py", line 334, in send_message
    result = await self.request(api.Methods.SEND_MESSAGE, payload)
  File "/home/wish/Projects/AnonimXChat/AnonChatTg/venv/lib/python3.10/site-packages/aiogram/bot/base.py", line 231, in request
    return await api.make_request(await self.get_session(), self.server, self.__token, method, data, files,
  File "/home/wish/Projects/AnonimXChat/AnonChatTg/venv/lib/python3.10/site-packages/aiogram/bot/api.py", line 140, in make_request
    return check_result(method, response.content_type, response.status, await response.text())
  File "/home/wish/Projects/AnonimXChat/AnonChatTg/venv/lib/python3.10/site-packages/aiogram/bot/api.py", line 115, in check_result
    exceptions.BadRequest.detect(description)
  File "/home/wish/Projects/AnonimXChat/AnonChatTg/venv/lib/python3.10/site-packages/aiogram/utils/exceptions.py", line 140, in detect
    raise err(cls.text or description)
aiogram.utils.exceptions.ChatNotFound: Chat not found
2022-05-30 05:38:24,045 - INFO -Stop polling...
2022-05-30 05:38:24,048 - WARNING -Goodbye!
